import { fireEvent, render, screen } from '@testing-library/react';
import React from 'react';
import { beforeEach, describe, expect, it, type MockInstance, vi } from 'vitest';
import ErrorBoundary from '../ErrorBoundary';

// Mock component that throws an error
const ThrowError = ({ shouldThrow }: { shouldThrow: boolean }) => {
  if (shouldThrow) {
    throw new Error('Test error');
  }
  return <div>No error</div>;
};

// Test component for retry functionality
const TestComponent = () => {
  const [shouldThrow, setShouldThrow] = React.useState(true);

  React.useEffect(() => {
    const timer = setTimeout(() => setShouldThrow(false), 100);
    return () => clearTimeout(timer);
  }, []);

  return <ThrowError shouldThrow={shouldThrow} />;
};

describe('ErrorBoundary', () => {
  let consoleError: MockInstance;

  beforeEach(() => {
    // Mock console.error to avoid noise in tests
    consoleError = vi.spyOn(console, 'error').mockImplementation(() => {});
  });

  afterEach(() => {
    consoleError.mockRestore();
  });

  it('renders children when there is no error', () => {
    render(
      <ErrorBoundary>
        <ThrowError shouldThrow={false} />
      </ErrorBoundary>
    );

    expect(screen.getByText('No error')).toBeInTheDocument();
  });

  it('renders error UI when child component throws', () => {
    render(
      <ErrorBoundary>
        <ThrowError shouldThrow={true} />
      </ErrorBoundary>
    );

    expect(screen.getByText('Something went wrong')).toBeInTheDocument();
    expect(screen.getByText(/We encountered an unexpected error/)).toBeInTheDocument();
    expect(screen.getByRole('button', { name: /try again/i })).toBeInTheDocument();
    expect(screen.getByRole('button', { name: /refresh page/i })).toBeInTheDocument();
  });

  it('calls onError callback when error occurs', () => {
    const onError = vi.fn();

    render(
      <ErrorBoundary onError={onError}>
        <ThrowError shouldThrow={true} />
      </ErrorBoundary>
    );

    expect(onError).toHaveBeenCalledWith(
      expect.any(Error),
      expect.objectContaining({
        componentStack: expect.any(String),
      })
    );
  });

  it('renders custom fallback when provided', () => {
    const customFallback = <div>Custom error message</div>;

    render(
      <ErrorBoundary fallback={customFallback}>
        <ThrowError shouldThrow={true} />
      </ErrorBoundary>
    );

    expect(screen.getByText('Custom error message')).toBeInTheDocument();
    expect(screen.queryByText('Something went wrong')).not.toBeInTheDocument();
  });

  it('resets error state when retry button is clicked', () => {
    render(
      <ErrorBoundary>
        <TestComponent />
      </ErrorBoundary>
    );

    // Error should be shown initially
    expect(screen.getByText('Something went wrong')).toBeInTheDocument();

    // Click retry button
    fireEvent.click(screen.getByRole('button', { name: /try again/i }));

    // Component should be rendered again (though it might still error)
    // The important thing is that the error boundary reset its state
    expect(consoleError).toHaveBeenCalled();
  });

  it('shows error details in development mode', () => {
    const originalEnv = process.env.NODE_ENV;
    process.env.NODE_ENV = 'development';

    render(
      <ErrorBoundary>
        <ThrowError shouldThrow={true} />
      </ErrorBoundary>
    );

    expect(screen.getByText('Error Details (Development)')).toBeInTheDocument();

    process.env.NODE_ENV = originalEnv;
  });

  it('hides error details in production mode', () => {
    const originalEnv = process.env.NODE_ENV;
    process.env.NODE_ENV = 'production';

    render(
      <ErrorBoundary>
        <ThrowError shouldThrow={true} />
      </ErrorBoundary>
    );

    expect(screen.queryByText('Error Details (Development)')).not.toBeInTheDocument();

    process.env.NODE_ENV = originalEnv;
  });
});
